<sdf version='1.7'>
  <model name='grogu'>
    <link name='base_link'>
      <inertial>
        <pose>0 0 0 0 -0 0</pose>
        <mass>36</mass>
        <inertia>
          <ixx>2.28864</ixx>
          <ixy>0</ixy>
          <ixz>0</ixz>
          <iyy>5.10398</iyy>
          <iyz>0</iyz>
          <izz>3.43147</izz>
        </inertia>
      </inertial>
      <collision name='base_link_collision'>
        <pose>0 0 0 1.57 0 -1.57</pose>
        <geometry>
          <mesh>
            <scale>1 1 1</scale>
            <uri>file:///home/spirolife/ros2_ws/install/scout_description/share/scout_description/meshes/grogu_base_link2.dae</uri>
          </mesh>
        </geometry>
      </collision>
      <collision name='base_link_fixed_joint_lump__camera_collision_collision_1'>
        <pose>0.27 0 0.03 0 -0 0</pose>
        <geometry>
          <cylinder>
            <length>0.01</length>
            <radius>0.012</radius>
          </cylinder>
        </geometry>
      </collision>
      <collision name='base_link_fixed_joint_lump__lidar_sensor_collision_collision_2'>
        <pose>-0.052 0 0.071 0 -0 0</pose>
        <geometry>
          <cylinder>
            <length>0.055</length>
            <radius>0.0508</radius>
          </cylinder>
        </geometry>
      </collision>
      <visual name='base_link_visual'>
        <pose>0 0 0 1.57 0 -1.57</pose>
        <geometry>
          <mesh>
            <scale>1 1 1</scale>
            <uri>file:///home/spirolife/ros2_ws/install/scout_description/share/scout_description/meshes/grogu_base_link2.dae</uri>
          </mesh>
        </geometry>
      </visual>
      <visual name='base_link_fixed_joint_lump__camera_visual_visual_1'>
        <pose>0.27 0 0.03 0 1.5708 0</pose>
        <geometry>
          <cylinder>
            <length>0.01</length>
            <radius>0.012</radius>
          </cylinder>
        </geometry>
      </visual>
      <visual name='base_link_fixed_joint_lump__imu_visual_visual_2'>
        <pose>0.01 0 0.2 0 1.5708 0</pose>
        <geometry>
          <cylinder>
            <length>0.01</length>
            <radius>0.012</radius>
          </cylinder>
        </geometry>
      </visual>
      <visual name='base_link_fixed_joint_lump__lidar_sensor_visual_visual_3'>
        <pose>-0.064 0 0.071 0 -0 0</pose>
        <geometry>
          <cylinder>
            <length>0.055</length>
            <radius>0.0508</radius>
          </cylinder>
        </geometry>
      </visual>
      <sensor name='camera' type='depth'>
        <visualize>1</visualize>
        <update_rate>10</update_rate>
        <camera>
          <horizontal_fov>1.098</horizontal_fov>
          <image>
            <format>R8G8B8</format>
            <width>640</width>
            <height>480</height>
          </image>
          <clip>
            <near>0.05</near>
            <far>8</far>
          </clip>
        </camera>
        <plugin name='camera_controller' filename='libgazebo_ros_camera.so'>
          <frame_name>base_scan_camera_optical</frame_name>
        </plugin>
        <pose>0.26 0 0.03 0 -0 0</pose>
        <parent link='base_scan_camera'/>
        <origin rpy='0.0 0.0 0.0' xyz='0.26 0.0 0.03'/>
      </sensor>
      <gravity>1</gravity>
      <sensor name='imu_sensor' type='imu'>
        <always_on>1</always_on>
        <update_rate>100</update_rate>
        <visualize>1</visualize>
        <topic>__default_topic__</topic>
        <plugin name='imu_plugin' filename='libgazebo_ros_imu_sensor.so'>
          <topicName>imu</topicName>
          <bodyName>inertial_link</bodyName>
          <updateRateHZ>10.0</updateRateHZ>
          <gaussianNoise>0.0</gaussianNoise>
          <xyzOffset>0 0 0</xyzOffset>
          <rpyOffset>0 0 0</rpyOffset>
          <frameName>inertial_link</frameName>
          <initialOrientationAsReference>0</initialOrientationAsReference>
        </plugin>
        <pose>0 0 0 0 -0 0</pose>
      </sensor>
      <sensor name='hls_lfcd_lds' type='ray'>
        <visualize>0</visualize>
        <update_rate>10</update_rate>
        <ray>
          <scan>
            <horizontal>
              <samples>64</samples>
              <resolution>1</resolution>
              <min_angle>-3.14</min_angle>
              <max_angle>3.14</max_angle>
            </horizontal>
            <vertical>
              <samples>64</samples>
              <resolution>1</resolution>
              <min_angle>-0.5</min_angle>
              <max_angle>0.5</max_angle>
            </vertical>
          </scan>
          <range>
            <min>0.12</min>
            <max>3.5</max>
            <resolution>0.015</resolution>
          </range>
          <noise>
            <type>gaussian</type>
            <mean>0</mean>
            <stddev>0.01</stddev>
          </noise>
        </ray>
        <plugin name='laser_controller' filename='libgazebo_ros_ray_sensor.so'>
          <frame_name>base_scan_lidar</frame_name>
        </plugin>
        <pose>-0.032 0 0.171 0 -0 0</pose>
        <origin rpy='0 0 0' xyz='0.0 0.0 0.0'/>
      </sensor>
    </link>
    <joint name='front_left_wheel' type='revolute'>
      <pose relative_to='base_link'>0.231976 0.208252 -0.100998 -1.57 0 0</pose>
      <parent>base_link</parent>
      <child>front_left_wheel_link</child>
      <axis>
        <xyz>0 0 1</xyz>
        <limit>
          <lower>-1e+16</lower>
          <upper>1e+16</upper>
        </limit>
        <dynamics>
          <spring_reference>0</spring_reference>
          <spring_stiffness>0</spring_stiffness>
        </dynamics>
      </axis>
    </joint>
    <link name='front_left_wheel_link'>
      <pose relative_to='front_left_wheel'>0 0 0 0 -0 0</pose>
      <inertial>
        <pose>0 0 0 0 -0 0</pose>
        <mass>3</mass>
        <inertia>
          <ixx>0.7171</ixx>
          <ixy>0</ixy>
          <ixz>0</ixz>
          <iyy>0.7171</iyy>
          <iyz>0</iyz>
          <izz>0.1361</izz>
        </inertia>
      </inertial>
      <collision name='front_left_wheel_link_collision'>
        <pose>0 0 0 0 -0 0</pose>
        <geometry>
          <mesh>
            <scale>1 1 1</scale>
            <uri>model://scout_description/meshes/wheel.dae</uri>
          </mesh>
        </geometry>
      </collision>
      <visual name='front_left_wheel_link_visual'>
        <pose>0 0 0 0 -0 0</pose>
        <geometry>
          <mesh>
            <scale>1 1 1</scale>
            <uri>model://scout_description/meshes/wheel.dae</uri>
          </mesh>
        </geometry>
      </visual>
    </link>
    <joint name='front_right_wheel' type='revolute'>
      <pose relative_to='base_link'>0.231976 -0.208252 -0.099998 1.57 -0 0</pose>
      <parent>base_link</parent>
      <child>front_right_wheel_link</child>
      <axis>
        <xyz>0 0 -1</xyz>
        <limit>
          <lower>-1e+16</lower>
          <upper>1e+16</upper>
        </limit>
        <dynamics>
          <spring_reference>0</spring_reference>
          <spring_stiffness>0</spring_stiffness>
        </dynamics>
      </axis>
    </joint>
    <link name='front_right_wheel_link'>
      <pose relative_to='front_right_wheel'>0 0 0 0 -0 0</pose>
      <inertial>
        <pose>0 0 0 0 -0 0</pose>
        <mass>3</mass>
        <inertia>
          <ixx>0.7171</ixx>
          <ixy>0</ixy>
          <ixz>0</ixz>
          <iyy>0.7171</iyy>
          <iyz>0</iyz>
          <izz>0.1361</izz>
        </inertia>
      </inertial>
      <collision name='front_right_wheel_link_collision'>
        <pose>0 0 0 0 -0 0</pose>
        <geometry>
          <mesh>
            <scale>1 1 1</scale>
            <uri>model://scout_description/meshes/wheel.dae</uri>
          </mesh>
        </geometry>
        <surface>
          <contact>
            <ode>
              <kp>1e+07</kp>
              <kd>1</kd>
              <min_depth>0.001</min_depth>
            </ode>
          </contact>
          <friction>
            <ode>
              <mu>1</mu>
              <mu2>0.9</mu2>
              <fdir1>1 0 0</fdir1>
            </ode>
          </friction>
        </surface>
        <max_contacts>64</max_contacts>
      </collision>
      <visual name='front_right_wheel_link_visual'>
        <pose>0 0 0 0 -0 0</pose>
        <geometry>
          <mesh>
            <scale>1 1 1</scale>
            <uri>model://scout_description/meshes/wheel.dae</uri>
          </mesh>
        </geometry>
      </visual>
    </link>
    <joint name='rear_left_wheel' type='revolute'>
      <pose relative_to='base_link'>-0.231976 0.208252 -0.100998 -1.57 0 0</pose>
      <parent>base_link</parent>
      <child>rear_left_wheel_link</child>
      <axis>
        <xyz>0 0 1</xyz>
        <limit>
          <lower>-1e+16</lower>
          <upper>1e+16</upper>
        </limit>
        <dynamics>
          <spring_reference>0</spring_reference>
          <spring_stiffness>0</spring_stiffness>
        </dynamics>
      </axis>
    </joint>
    <link name='rear_left_wheel_link'>
      <pose relative_to='rear_left_wheel'>0 0 0 0 -0 0</pose>
      <inertial>
        <pose>0 0 0 0 -0 0</pose>
        <mass>3</mass>
        <inertia>
          <ixx>0.7171</ixx>
          <ixy>0</ixy>
          <ixz>0</ixz>
          <iyy>0.7171</iyy>
          <iyz>0</iyz>
          <izz>0.1361</izz>
        </inertia>
      </inertial>
      <collision name='rear_left_wheel_link_collision'>
        <pose>0 0 0 0 -0 0</pose>
        <geometry>
          <mesh>
            <scale>1 1 1</scale>
            <uri>model://scout_description/meshes/wheel.dae</uri>
          </mesh>
        </geometry>
        <surface>
          <contact>
            <ode>
              <kp>1e+07</kp>
              <kd>1</kd>
              <min_depth>0.001</min_depth>
            </ode>
          </contact>
          <friction>
            <ode>
              <mu>1</mu>
              <mu2>0.9</mu2>
              <fdir1>1 0 0</fdir1>
            </ode>
          </friction>
        </surface>
        <max_contacts>64</max_contacts>
      </collision>
      <visual name='rear_left_wheel_link_visual'>
        <pose>0 0 0 0 -0 0</pose>
        <geometry>
          <mesh>
            <scale>1 1 1</scale>
            <uri>model://scout_description/meshes/wheel.dae</uri>
          </mesh>
        </geometry>
      </visual>
    </link>
    <joint name='rear_right_wheel' type='revolute'>
      <pose relative_to='base_link'>-0.231976 -0.208252 -0.099998 1.57 -0 0</pose>
      <parent>base_link</parent>
      <child>rear_right_wheel_link</child>
      <axis>
        <xyz>0 0 -1</xyz>
        <limit>
          <lower>-1e+16</lower>
          <upper>1e+16</upper>
        </limit>
        <dynamics>
          <spring_reference>0</spring_reference>
          <spring_stiffness>0</spring_stiffness>
        </dynamics>
      </axis>
    </joint>
    <link name='rear_right_wheel_link'>
      <pose relative_to='rear_right_wheel'>0 0 0 0 -0 0</pose>
      <inertial>
        <pose>0 0 0 0 -0 0</pose>
        <mass>3</mass>
        <inertia>
          <ixx>0.7171</ixx>
          <ixy>0</ixy>
          <ixz>0</ixz>
          <iyy>0.7171</iyy>
          <iyz>0</iyz>
          <izz>0.1361</izz>
        </inertia>
      </inertial>
      <collision name='rear_right_wheel_link_collision'>
        <pose>0 0 0 0 -0 0</pose>
        <geometry>
          <mesh>
            <scale>1 1 1</scale>
            <uri>model://scout_description/meshes/wheel.dae</uri>
          </mesh>
        </geometry>
        <surface>
          <contact>
            <ode>
              <kp>1e+07</kp>
              <kd>1</kd>
              <min_depth>0.001</min_depth>
            </ode>
          </contact>
          <friction>
            <ode>
              <mu>1</mu>
              <mu2>0.9</mu2>
              <fdir1>1 0 0</fdir1>
            </ode>
          </friction>
        </surface>
        <max_contacts>64</max_contacts>
      </collision>
      <visual name='rear_right_wheel_link_visual'>
        <pose>0 0 0 0 -0 0</pose>
        <geometry>
          <mesh>
            <scale>1 1 1</scale>
            <uri>model://scout_description/meshes/wheel.dae</uri>
          </mesh>
        </geometry>
      </visual>
    </link>
    <plugin name='gazebo_ros_control' filename='libgazebo_ros_control.so'>
      <robotNamespace>/</robotNamespace>
    </plugin>
    <static>0</static>
    <plugin name='skid_steer_drive_controller' filename='libgazebo_ros_diff_drive.so'>
      <updateRate>100.0</updateRate>
      <robotNamespace/>
      <num_wheel_pairs>2</num_wheel_pairs>
      <left_joint>front_left_wheel</left_joint>
      <right_joint>front_right_wheel</right_joint>
      <left_joint>rear_left_wheel</left_joint>
      <right_joint>rear_right_wheel</right_joint>
      <wheel_separation>0.8</wheel_separation>
      <wheel_separation>0.8</wheel_separation>
      <wheel_diameter>0.15918</wheel_diameter>
      <wheel_diameter>0.15918</wheel_diameter>
      <robot_base_frame>base_link</robot_base_frame>
      <odometry_frame>odom</odometry_frame>
      <max_wheel_torque>1000</max_wheel_torque>
      <publish_odom>1</publish_odom>
      <publish_odom_tf>1</publish_odom_tf>
      <publish_wheel_tf>1</publish_wheel_tf>
    </plugin>
  </model>
</sdf>
