<?xml version="1.0" ?>
<!-- =================================================================================== -->
<!-- |    This document was autogenerated by xacro from ./mini.xacro                   | -->
<!-- |    EDITING THIS FILE BY HAND IS NOT RECOMMENDED                                 | -->
<!-- =================================================================================== -->
<robot name="scout_mini">
  <!--    <xacro:property name="track" value="0.3426" />
    <xacro:property name="wheelbase" value="0.3181"/>
    <xacro:property name="wheel_vertical_offset" value="-0.160000047342231" />-->
  <!-- Base link -->
  <link name="base_link">
    <visual>
      <origin rpy="1.57 0 -1.57" xyz="0 0 0.0"/>
      <geometry>
        <mesh filename="package://scout_description/meshes/scout_mini_base_link2.dae"/>
      </geometry>
    </visual>
    <collision>
      <origin rpy="1.57 0 -1.57" xyz="0 0 0"/>
      <geometry>
        <mesh filename="package://scout_description/meshes/scout_mini_base_link2.dae"/>
      </geometry>
    </collision>
  </link>
  <link name="base_scan">
    <collision name="lidar_sensor_collision">
      <origin rpy="0 0 0" xyz="-0.020 0 0.161"/>
      <geometry>
        <cylinder length="0.055" radius="0.0508"/>
      </geometry>
    </collision>
    <visual name="lidar_sensor_visual">
      <origin rpy="0 0 0" xyz="-0.032 0 0.171"/>
      <geometry>
        <cylinder length="0.055" radius="0.0508"/>
      </geometry>
    </visual>
    <sensor name="hls_lfcd_lds" type="ray">
      <always_on>true</always_on>
      <visualize>true</visualize>
      <pose>-0.032 0 0.171 0 0 0</pose>
      <update_rate>5</update_rate>
      <ray>
        <scan>
          <horizontal>
            <samples>360</samples>
            <resolution>1.000000</resolution>
            <min_angle>0.000000</min_angle>
            <max_angle>6.280000</max_angle>
          </horizontal>
        </scan>
        <range>
          <min>0.120000</min>
          <max>3.5</max>
          <resolution>0.015000</resolution>
        </range>
        <noise>
          <type>gaussian</type>
          <mean>0.0</mean>
          <stddev>0.01</stddev>
        </noise>
      </ray>
      <plugin filename="libgazebo_ros_ray_sensor.so" name="laser_scan">
        <ros>
          <!-- <namespace>/tb3</namespace> -->
          <remapping>~/out:=scan</remapping>
        </ros>
        <output_type>sensor_msgs/LaserScan</output_type>
        <frame_name>base_scan</frame_name>
      </plugin>
    </sensor>
  </link>
  <!-- <joint name="chassis_link_joint" type="fixed">
        <origin xyz="0 0 ${wheel_radius - wheel_vertical_offset}" rpy="0 0 0" />
        <parent link="base_link" />
        <child link="chassis_link" />
    </joint> -->
  <link name="inertial_link">
    <inertial>
      <mass value="60"/>
      <origin xyz="0.0 0.0 0.0"/>
      <inertia ixx="2.288641" ixy="0" ixz="0" iyy="5.103976" iyz="0" izz="3.431465"/>
    </inertial>
  </link>
  <joint name="inertial_joint" type="fixed">
    <origin rpy="0 0 0" xyz="0 0 0"/>
    <parent link="base_link"/>
    <child link="inertial_link"/>
  </joint>
  <joint name="lidar_joint" type="fixed">
    <parent link="base_link"/>
    <child link="base_scan"/>
    <origin rpy="0 0 0" xyz="-0.032 0 0.171"/>
    <axis rpy="0 0 0" xyz="0 0 1"/>
  </joint>
  <!-- For testing, hang the robot up in the air -->
  <!-- <link name="world" />
    <joint name="world_to_base_link=" type="fixed">
        <origin xyz="0 0 0.5" rpy="0 0 0" />
        <parent link="world"/>
        <child link="base_link"/>
    </joint> -->
  <link name="front_left_wheel_link">
    <!--<inertial>
                <mass value="3" />
                <origin
                        xyz="0.162297526351145 -0.159063056237197 -0.159999952657767"
                        rpy="0 0 0" />
                        <inertia ixx="0.7171" ixy="0" ixz="0" iyy="0.1361" iyz="0" izz="0.7171" />
                   </inertial>
            <visual>
                <origin xyz="0 0 0" rpy="0 0 0" />
                <geometry>
                    <mesh filename="package://scout_description/meshes/wheel.dae" />
                </geometry>
            </visual>-->
    <inertial>
      <mass value="3"/>
      <origin xyz="0 0 0"/>
      <inertia ixx="0.7171" ixy="0" ixz="0" iyy="0.7171" iyz="0" izz="0.1361"/>
      <!--<inertia ixx="0" ixy="0" ixz="0" iyy="0" iyz="0" izz="0" />-->
    </inertial>
    <visual>
      <origin rpy="0 0 0" xyz="0 0 0"/>
      <geometry>
        <mesh filename="package://scout_description/meshes/wheel.dae"/>
      </geometry>
    </visual>
    <collision>
      <origin rpy="0 0 0" xyz="0 0 0"/>
      <geometry>
        <mesh filename="package://scout_description/meshes/wheel.dae"/>
      </geometry>
    </collision>
  </link>
  <joint name="front_left_wheel" type="continuous">
    <!--<origin
                  xyz="0.14547 0.20835 -0.07424"
                  rpy="0 1.57 0" />-->
    <parent link="base_link"/>
    <child link="front_left_wheel_link"/>
    <origin rpy="-1.57 0 0" xyz="0.2319755 0.2082515 -0.100998"/>
    <axis rpy="0 0 0" xyz="0 0 1"/>
  </joint>
  <link name="rear_left_wheel_link">
    <!--<inertial>
            <mass value="3" />
                <origin
                        xyz="0.162297526351148 0.159063056237198 -0.160000047342231"
                        rpy="0 0 0" />
                        <inertia ixx="0.7171" ixy="0" ixz="0" iyy="0.1361" iyz="0" izz="0.7171" />
            </inertial>
            <visual>
                <origin xyz="0 0 0" rpy="0 0 0" />
                <geometry>
                    <mesh filename="package://scout_description/meshes/wheel.dae" />
                </geometry>
            </visual>-->
    <inertial>
      <mass value="3"/>
      <origin xyz="0 0 0"/>
      <inertia ixx="0.7171" ixy="0" ixz="0" iyy="0.7171" iyz="0" izz="0.1361"/>
      <!--<inertia ixx="0" ixy="0" ixz="0" iyy="0" iyz="0" izz="0" />-->
    </inertial>
    <visual>
      <origin rpy="0 0 0" xyz="0 0 0"/>
      <geometry>
        <mesh filename="package://scout_description/meshes/wheel.dae"/>
      </geometry>
    </visual>
    <collision>
      <origin rpy="0 0 0" xyz="0 0 0"/>
      <geometry>
        <mesh filename="package://scout_description/meshes/wheel.dae"/>
      </geometry>
    </collision>
  </link>
  <joint name="rear_left_wheel" type="continuous">
    <!--<origin
                  xyz="-0.17453 0.20835 -0.07424"
                  rpy="0 -1.57 0" />-->
    <parent link="base_link"/>
    <child link="rear_left_wheel_link"/>
    <origin rpy="-1.57 0 0" xyz="-0.2319755 0.2082515 -0.100998"/>
    <axis rpy="0 0 0" xyz="0 0 1"/>
  </joint>
  <link name="front_right_wheel_link">
    <!--<inertial>
            <mass value="3" />
                <origin
                        xyz="-0.235088020493741 -0.0575697183039213 -0.16000004734223"
                        rpy="0 0 0" />
                        <inertia ixx="0.7171" ixy="0" ixz="0" iyy="0.1361" iyz="0" izz="0.7171" />
            </inertial>
            <visual>
                <origin xyz="0 0 0" rpy="0 0 0" />
                <geometry>
                    <mesh filename="package://scout_description/meshes/wheel.dae" />
                </geometry>
            </visual>-->
    <inertial>
      <mass value="3"/>
      <origin xyz="0 0 0"/>
      <inertia ixx="0.7171" ixy="0" ixz="0" iyy="0.7171" iyz="0" izz="0.1361"/>
      <!--<inertia ixx="0" ixy="0" ixz="0" iyy="0" iyz="0" izz="0" />-->
    </inertial>
    <visual>
      <origin rpy="0 0 0" xyz="0 0 0"/>
      <geometry>
        <mesh filename="package://scout_description/meshes/wheel.dae"/>
      </geometry>
    </visual>
    <collision>
      <origin rpy="0 0 0" xyz="0 0 0"/>
      <geometry>
        <mesh filename="package://scout_description/meshes/wheel.dae"/>
      </geometry>
    </collision>
  </link>
  <joint name="front_right_wheel" type="continuous">
    <!--<origin
                  xyz="-0.17453 -0.24424 -0.07424"
                  rpy="0 -1.57 0" />-->
    <parent link="base_link"/>
    <child link="front_right_wheel_link"/>
    <origin rpy="1.57 0 0" xyz="0.2319755 -0.2082515 -0.099998"/>
    <axis rpy="0 0 0" xyz="0 0 -1"/>
  </joint>
  <link name="rear_right_wheel_link">
    <!--<inertial>
        <mass value="3" />
            <origin
                    xyz="0.235244832119832 -0.0585653794466942 -0.206994929144493"
                    rpy="0 0 0" />
                    <inertia ixx="0.7171" ixy="0" ixz="0" iyy="0.1361" iyz="0" izz="0.7171" />
        </inertial>
        <visual>
            <origin xyz="0 0 0" rpy="0 0 0" />
            <geometry>
                <mesh filename="package://scout_description/meshes/wheel.dae" />
            </geometry>
        </visual>-->
    <inertial>
      <mass value="3"/>
      <origin xyz="0 0 0"/>
      <inertia ixx="0.7171" ixy="0" ixz="0" iyy="0.7171" iyz="0" izz="0.1361"/>
      <!--<inertia ixx="0" ixy="0" ixz="0" iyy="0" iyz="0" izz="0" />-->
    </inertial>
    <visual>
      <origin rpy="0 0 0" xyz="0 0 0"/>
      <geometry>
        <mesh filename="package://scout_description/meshes/wheel.dae"/>
      </geometry>
    </visual>
    <collision>
      <origin rpy="0 0 0" xyz="0 0 0"/>
      <geometry>
        <mesh filename="package://scout_description/meshes/wheel.dae"/>
      </geometry>
    </collision>
  </link>
  <joint name="rear_right_wheel" type="continuous">
    <!--<origin
                  xyz="0.19247 -0.24486 -0.073441"
                  rpy="-0 1.57 0" />-->
    <parent link="base_link"/>
    <child link="rear_right_wheel_link"/>
    <origin rpy="1.57 0 0" xyz="-0.2319755 -0.2082515 -0.099998"/>
    <axis rpy="0 0 0" xyz="0 0 -1"/>
  </joint>
  <!-- This file is a placeholder which is included by default from
       husky.urdf.xacro. If a robot is being customized and requires
       additional URDF, set the HUSKY_URDF_EXTRAS environment variable
       to the full path of the file you would like included. -->
  <!-- Additional definitions for simulation -->
  <!-- <gazebo reference="base_link">
        <material>Gazebo/Grey</material>
    </gazebo> -->
  <transmission name="front_right_wheel_trans" type="SimpleTransmission">
    <type>transmission_interface/SimpleTransmission</type>
    <actuator name="front_right_wheel_motor">
      <mechanicalReduction>1</mechanicalReduction>
    </actuator>
    <joint name="front_right_wheel">
      <hardwareInterface>hardware_interface/VelocityJointInterface</hardwareInterface>
    </joint>
  </transmission>
  <transmission name="front_left_wheel_trans" type="SimpleTransmission">
    <type>transmission_interface/SimpleTransmission</type>
    <actuator name="front_left_wheel_motor">
      <mechanicalReduction>1</mechanicalReduction>
    </actuator>
    <joint name="front_left_wheel">
      <hardwareInterface>hardware_interface/VelocityJointInterface</hardwareInterface>
    </joint>
  </transmission>
  <transmission name="rear_left_wheel_trans" type="SimpleTransmission">
    <type>transmission_interface/SimpleTransmission</type>
    <actuator name="rear_left_wheel_motor">
      <mechanicalReduction>1</mechanicalReduction>
    </actuator>
    <joint name="rear_left_wheel">
      <hardwareInterface>hardware_interface/VelocityJointInterface</hardwareInterface>
    </joint>
  </transmission>
  <transmission name="rear_right_wheel_trans" type="SimpleTransmission">
    <type>transmission_interface/SimpleTransmission</type>
    <actuator name="rear_right_wheel_motor">
      <mechanicalReduction>1</mechanicalReduction>
    </actuator>
    <joint name="rear_right_wheel">
      <hardwareInterface>hardware_interface/VelocityJointInterface</hardwareInterface>
    </joint>
  </transmission>
  <gazebo>
    <plugin filename="libgazebo_ros_control.so" name="gazebo_ros_control">
      <robotNamespace>/</robotNamespace>
    </plugin>
  </gazebo>
  <gazebo reference="front_right_wheel_link">
    <mu1 value="1.0"/>
    <mu2 value="0.9"/>
    <kp value="10000000.0"/>
    <kd value="1.0"/>
    <fdir1 value="1 0 0"/>
    <minDepth value="0.001"/>
    <maxContacts value="64"/>
  </gazebo>
  <gazebo reference="front_right_wheel_link">
    <mu1 value="1.0"/>
    <mu2 value="0.9"/>
    <kp value="10000000.0"/>
    <kd value="1.0"/>
    <fdir1 value="1 0 0"/>
    <minDepth value="0.001"/>
    <maxContacts value="64"/>
  </gazebo>
  <gazebo reference="rear_left_wheel_link">
    <mu1 value="1.0"/>
    <mu2 value="0.9"/>
    <kp value="10000000.0"/>
    <kd value="1.0"/>
    <fdir1 value="1 0 0"/>
    <minDepth value="0.001"/>
    <maxContacts value="64"/>
  </gazebo>
  <gazebo reference="rear_right_wheel_link">
    <mu1 value="1.0"/>
    <mu2 value="0.9"/>
    <kp value="10000000.0"/>
    <kd value="1.0"/>
    <fdir1 value="1 0 0"/>
    <minDepth value="0.001"/>
    <maxContacts value="64"/>
  </gazebo>
  <gazebo reference="base_can">
    <sensor name="hls_lfcd_lds" type="ray">
      <always_on>true</always_on>
      <visualize>true</visualize>
      <pose>-0.032 0 0.171 0 0 0</pose>
      <update_rate>5</update_rate>
      <ray>
        <scan>
          <horizontal>
            <samples>360</samples>
            <resolution>1.000000</resolution>
            <min_angle>0.000000</min_angle>
            <max_angle>6.280000</max_angle>
          </horizontal>
        </scan>
        <range>
          <min>0.120000</min>
          <max>3.5</max>
          <resolution>0.015000</resolution>
        </range>
        <noise>
          <type>gaussian</type>
          <mean>0.0</mean>
          <stddev>0.01</stddev>
        </noise>
      </ray>
      <plugin filename="libgazebo_ros_ray_sensor.so" name="laser_scan">
        <ros>
          <!-- <namespace>/tb3</namespace> -->
          <remapping>~/out:=scan</remapping>
        </ros>
        <output_type>sensor_msgs/LaserScan</output_type>
        <frame_name>base_scan</frame_name>
      </plugin>
    </sensor>
  </gazebo>
  <gazebo>
    <!-- <plugin name="skid_steer_drive_controller" filename="libgazebo_ros_skid_steer_drive.so"> -->
    <plugin filename="libgazebo_ros_diff_drive.so" name="skid_steer_drive_controller">
      <updateRate>100.0</updateRate>
      <robotNamespace/>
      <num_wheel_pairs>2</num_wheel_pairs>
      <left_joint>front_left_wheel</left_joint>
      <right_joint>front_right_wheel</right_joint>
      <left_joint>rear_left_wheel</left_joint>
      <right_joint>rear_right_wheel</right_joint>
      <wheel_separation>0.8</wheel_separation>
      <wheel_separation>0.8</wheel_separation>
      <wheel_diameter>0.15918</wheel_diameter>
      <wheel_diameter>0.15918</wheel_diameter>
      <robot_base_frame>base_link</robot_base_frame>
      <odometry_frame>odom</odometry_frame>
      <max_wheel_torque>1000</max_wheel_torque>
      <!-- <ros>
                <remapping>cmd_vel:=cmd_vel</remapping>
                <remapping>odom:=odom</remapping>
            </ros> -->
      <publish_odom>true</publish_odom>
      <publish_odom_tf>true</publish_odom_tf>
      <publish_wheel_tf>true</publish_wheel_tf>
      <!-- <broadcastTF>true</broadcastTF>
            <odometryTopic>odom</odometryTopic>
            <odometryFrame>odom</odometryFrame>
            <covariance_x>0.000100</covariance_x>
            <covariance_y>0.000100</covariance_y>
            <covariance_yaw>0.010000</covariance_yaw> -->
    </plugin>
  </gazebo>
  <!-- <gazebo>
        <plugin name="object_controller" filename="libgazebo_ros_planar_move.so">
            <commandTopic>cmd_vel</commandTopic>
            <odometryTopic>odom</odometryTopic>
            <odometryFrame>odom</odometryFrame>
            <odometryRate>20.0</odometryRate>
            <robotBaseFrame>base_footprint</robotBaseFrame>
        </plugin>
    </gazebo> -->
</robot>
