<sdf version='1.7'>
  <model name='scout_mini'>
    <link name='base_link'>
      <inertial>
        <pose>-2.9e-05 0 6.2e-05 0 -0 0</pose>
        <mass>18.01</mass>
        <inertia>
          <ixx>2.28976</ixx>
          <ixy>0</ixy>
          <ixz>5.7688e-05</ixz>
          <iyy>5.10513</iyy>
          <iyz>0</iyz>
          <izz>3.43249</izz>
        </inertia>
      </inertial>
      <collision name='base_link_collision'>
        <pose>0 0 0.008 0 -0 0</pose>
        <geometry>
          <box>
            <size>0.595 0.395 0.13</size>
          </box>
        </geometry>
      </collision>
      <collision name='base_link_fixed_joint_lump__base_scan_collision_1'>
        <pose>-0.052 0 0.111 0 -0 0</pose>
        <geometry>
          <cylinder>
            <length>0.055</length>
            <radius>0.0508</radius>
          </cylinder>
        </geometry>
        <surface>
          <contact>
            <ode/>
          </contact>
          <friction>
            <ode/>
          </friction>
        </surface>
      </collision>
      <visual name='base_link_visual'>
        <pose>0 0 0 1.5707 0 1.5707</pose>
        <geometry>
          <mesh>
            <scale>1 1 1</scale>
            <uri>model://scout_description/meshes/scout_mini/mini_base_link2.dae</uri>
          </mesh>
        </geometry>
      </visual>
      <visual name='base_link_fixed_joint_lump__base_scan_visual_1'>
        <pose>-0.064 0 0.121 0 -0 0</pose>
        <geometry>
          <mesh>
            <scale>0.001 0.001 0.001</scale>
            <uri>model://scout_description/meshes/scout_mini/lds.dae</uri>
          </mesh>
        </geometry>
      </visual>
      <gravity>1</gravity>
      <sensor name='imu_sensor' type='imu'>
        <always_on>1</always_on>
        <update_rate>100</update_rate>
        <visualize>1</visualize>
        <topic>__default_topic__</topic>
        <plugin name='imu_plugin' filename='libgazebo_ros_imu_sensor.so'>
          <topicName>imu</topicName>
          <bodyName>base_scan</bodyName>
          <updateRateHZ>100.0</updateRateHZ>
          <gaussianNoise>0.0</gaussianNoise>
          <xyzOffset>0 0 0</xyzOffset>
          <rpyOffset>0 0 0</rpyOffset>
          <frameName>imu_link</frameName>
          <initialOrientationAsReference>0</initialOrientationAsReference>
        </plugin>
        <pose>0 0 0 0 -0 0</pose>
      </sensor>
    </link>
    <joint name='front_left_wheel' type='revolute'>
      <pose relative_to='base_link'>0.226 0.245 -0.0905 0 -0 0</pose>
      <parent>base_link</parent>
      <child>front_left_wheel_link</child>
      <axis>
        <xyz>0 -1 0</xyz>
        <limit>
          <lower>-1e+16</lower>
          <upper>1e+16</upper>
        </limit>
        <dynamics>
          <spring_reference>0</spring_reference>
          <spring_stiffness>0</spring_stiffness>
        </dynamics>
      </axis>
    </joint>
    <link name='front_left_wheel_link'>
      <pose relative_to='front_left_wheel'>0 0 0 0 -0 0</pose>
      <inertial>
        <pose>0 0 0 0 -0 0</pose>
        <mass>1</mass>
        <inertia>
          <ixx>0.7171</ixx>
          <ixy>0</ixy>
          <ixz>0</ixz>
          <iyy>0.1361</iyy>
          <iyz>0</iyz>
          <izz>0.7171</izz>
        </inertia>
      </inertial>
      <collision name='front_left_wheel_link_collision'>
        <pose>0 0 0 1.57079 -0 0</pose>
        <geometry>
          <cylinder>
            <length>0.0852</length>
            <radius>0.0875</radius>
          </cylinder>
        </geometry>
      </collision>
      <visual name='front_left_wheel_link_visual'>
        <pose>-0.221 -0.225 0.0925 0 -0 0</pose>
        <geometry>
          <mesh>
            <scale>1 1 1</scale>
            <uri>model://scout_description/meshes/scout_mini/mini_wheel.dae</uri>
          </mesh>
        </geometry>
      </visual>
    </link>
    <joint name='front_right_wheel' type='revolute'>
      <pose relative_to='base_link'>0.226 -0.245 -0.0905 3.14 -0 0</pose>
      <parent>base_link</parent>
      <child>front_right_wheel_link</child>
      <axis>
        <xyz>0 -1 0</xyz>
        <limit>
          <lower>-1e+16</lower>
          <upper>1e+16</upper>
        </limit>
        <dynamics>
          <spring_reference>0</spring_reference>
          <spring_stiffness>0</spring_stiffness>
        </dynamics>
      </axis>
    </joint>
    <link name='front_right_wheel_link'>
      <pose relative_to='front_right_wheel'>0 0 0 0 -0 0</pose>
      <inertial>
        <pose>0 0 0 0 -0 0</pose>
        <mass>1</mass>
        <inertia>
          <ixx>0.7171</ixx>
          <ixy>0</ixy>
          <ixz>0</ixz>
          <iyy>0.1361</iyy>
          <iyz>0</iyz>
          <izz>0.7171</izz>
        </inertia>
      </inertial>
      <collision name='front_right_wheel_link_collision'>
        <pose>0 0 0 1.57079 -0 0</pose>
        <geometry>
          <cylinder>
            <length>0.0852</length>
            <radius>0.0875</radius>
          </cylinder>
        </geometry>
      </collision>
      <visual name='front_right_wheel_link_visual'>
        <pose>-0.221 -0.225 0.0925 0 -0 0</pose>
        <geometry>
          <mesh>
            <scale>1 1 1</scale>
            <uri>model://scout_description/meshes/scout_mini/mini_wheel.dae</uri>
          </mesh>
        </geometry>
      </visual>
    </link>
    <joint name='rear_left_wheel' type='revolute'>
      <pose relative_to='base_link'>-0.226 0.245 -0.0905 0 -0 0</pose>
      <parent>base_link</parent>
      <child>rear_left_wheel_link</child>
      <axis>
        <xyz>0 -1 0</xyz>
        <limit>
          <lower>-1e+16</lower>
          <upper>1e+16</upper>
        </limit>
        <dynamics>
          <spring_reference>0</spring_reference>
          <spring_stiffness>0</spring_stiffness>
        </dynamics>
      </axis>
    </joint>
    <link name='rear_left_wheel_link'>
      <pose relative_to='rear_left_wheel'>0 0 0 0 -0 0</pose>
      <inertial>
        <pose>0 0 0 0 -0 0</pose>
        <mass>1</mass>
        <inertia>
          <ixx>0.7171</ixx>
          <ixy>0</ixy>
          <ixz>0</ixz>
          <iyy>0.1361</iyy>
          <iyz>0</iyz>
          <izz>0.7171</izz>
        </inertia>
      </inertial>
      <collision name='rear_left_wheel_link_collision'>
        <pose>0 0 0 1.57079 -0 0</pose>
        <geometry>
          <cylinder>
            <length>0.0852</length>
            <radius>0.0875</radius>
          </cylinder>
        </geometry>
      </collision>
      <visual name='rear_left_wheel_link_visual'>
        <pose>-0.221 -0.225 0.0925 0 -0 0</pose>
        <geometry>
          <mesh>
            <scale>1 1 1</scale>
            <uri>model://scout_description/meshes/scout_mini/mini_wheel.dae</uri>
          </mesh>
        </geometry>
      </visual>
    </link>
    <joint name='rear_right_wheel' type='revolute'>
      <pose relative_to='base_link'>-0.226 -0.245 -0.0905 3.14 -0 0</pose>
      <parent>base_link</parent>
      <child>rear_right_wheel_link</child>
      <axis>
        <xyz>0 -1 0</xyz>
        <limit>
          <lower>-1e+16</lower>
          <upper>1e+16</upper>
        </limit>
        <dynamics>
          <spring_reference>0</spring_reference>
          <spring_stiffness>0</spring_stiffness>
        </dynamics>
      </axis>
    </joint>
    <link name='rear_right_wheel_link'>
      <pose relative_to='rear_right_wheel'>0 0 0 0 -0 0</pose>
      <inertial>
        <pose>0 0 0 0 -0 0</pose>
        <mass>1</mass>
        <inertia>
          <ixx>0.7171</ixx>
          <ixy>0</ixy>
          <ixz>0</ixz>
          <iyy>0.1361</iyy>
          <iyz>0</iyz>
          <izz>0.7171</izz>
        </inertia>
      </inertial>
      <collision name='rear_right_wheel_link_collision'>
        <pose>0 0 0 1.57079 -0 0</pose>
        <geometry>
          <cylinder>
            <length>0.0852</length>
            <radius>0.0875</radius>
          </cylinder>
        </geometry>
      </collision>
      <visual name='rear_right_wheel_link_visual'>
        <pose>-0.221 -0.225 0.0925 0 -0 0</pose>
        <geometry>
          <mesh>
            <scale>1 1 1</scale>
            <uri>model://scout_description/meshes/scout_mini/mini_wheel.dae</uri>
          </mesh>
        </geometry>
      </visual>
    </link>
    <static>0</static>
    <plugin name='gz::sim::systems::DiffDrive' filename='gz-sim-diff-drive-system'>
      <left_joint>rear_left_wheel</left_joint>
      <left_joint>front_left_wheel</left_joint>
      <right_joint>rear_right_wheel</right_joint>
      <right_joint>front_right_wheel</right_joint>
      <wheel_separation>0.287</wheel_separation>
      <wheel_radius>0.0875</wheel_radius>
      <max_linear_acceleration>3.5</max_linear_acceleration>
      <topic>cmd_vel</topic>
      <odom_topic>odom</odom_topic>
      <frame_id>odom</frame_id>
      <tf_topic>/tf</tf_topic>
      <odom_publisher_frequency>30</odom_publisher_frequency>
      <child_frame_id>base_footprint</child_frame_id>
    </plugin>
    <plugin name='gz::sim::systems::JointStatePublisher' filename='gz-sim-joint-state-publisher-system'>
      <topic>joint_states</topic>
      <joint_name>rear_left_wheel</joint_name>
      <joint_name>rear_right_wheel</joint_name>
      <joint_name>front_left_wheel</joint_name>
      <joint_name>front_right_wheel</joint_name>
    </plugin>
  </model>
</sdf>
