<?xml version="1.0" ?>
<robot name="scout_mini">
  <!-- Base link -->
  <link name="base_link">
    <visual>
      <origin rpy="1.5707 0  1.5707" xyz="0 0 0"/>
      <geometry>
        <mesh filename="package://scout_description/meshes/scout_mini/mini_base_link2.dae"/>
      </geometry>
    </visual>
    <collision>
      <origin rpy="0 0 0" xyz="0 0 0.008"/>
      <geometry>
        <box size="0.595 0.395 0.13"/>
      </geometry>
    </collision>
  </link>
  <link name="base_footprint"/>
  <joint name="base_footprint_joint" type="fixed">
    <origin rpy="0 0 0" xyz="0 0 -0.178"/>
    <parent link="base_link"/>
    <child link="base_footprint"/>
  </joint>
  <link name="inertial_link">
    <inertial>
      <mass value="18"/>
      <origin xyz="0.0 0.0 0.0"/>
      <inertia ixx="2.288641" ixy="0" ixz="0" iyy="5.103976" iyz="0" izz="3.431465"/>
    </inertial>
  </link>
  <joint name="inertial_joint" type="fixed">
    <origin rpy="0 0 0" xyz="0 0 0"/>
    <parent link="base_link"/>
    <child link="inertial_link"/>
  </joint>
  <link name="front_right_wheel_link">
    <inertial>
      <mass value="1"/>
      <origin xyz="0 0 0"/>
      <inertia ixx="0.7171" ixy="0" ixz="0" iyy="0.1361" iyz="0" izz="0.7171"/>
    </inertial>
    <visual>
      <!-- <origin xyz="0 0 0" rpy="0 0 0" /> -->
      <origin rpy="0 0 0" xyz="-0.221 -0.225 0.0925"/>
      <geometry>
        <mesh filename="package://scout_description/meshes/scout_mini/mini_wheel.dae"/>
      </geometry>
    </visual>
    <collision>
      <origin rpy="1.570795 0 0" xyz="0 0 0"/>
      <geometry>
        <cylinder length="0.0852" radius="0.0875"/>
      </geometry>
    </collision>
  </link>
  <joint name="front_right_wheel" type="continuous">
    <parent link="base_link"/>
    <child link="front_right_wheel_link"/>
    <origin rpy="3.14 0 0" xyz="0.226 -0.245 -0.0905"/>
    <axis rpy="0 0 0" xyz="0 -1 0"/>
  </joint>
  <link name="front_left_wheel_link">
    <inertial>
      <mass value="1"/>
      <origin xyz="0 0 0"/>
      <inertia ixx="0.7171" ixy="0" ixz="0" iyy="0.1361" iyz="0" izz="0.7171"/>
    </inertial>
    <visual>
      <!-- <origin xyz="0 0 0" rpy="0 0 0" /> -->
      <origin rpy="0 0 0" xyz="-0.221 -0.225 0.0925"/>
      <geometry>
        <mesh filename="package://scout_description/meshes/scout_mini/mini_wheel.dae"/>
      </geometry>
    </visual>
    <collision>
      <origin rpy="1.570795 0 0" xyz="0 0 0"/>
      <geometry>
        <cylinder length="0.0852" radius="0.0875"/>
      </geometry>
    </collision>
  </link>
  <joint name="front_left_wheel" type="continuous">
    <parent link="base_link"/>
    <child link="front_left_wheel_link"/>
    <origin rpy="0 0 0" xyz="0.226 0.245 -0.0905"/>
    <axis rpy="0 0 0" xyz="0 -1 0"/>
  </joint>
  <link name="rear_left_wheel_link">
    <inertial>
      <mass value="1"/>
      <origin xyz="0 0 0"/>
      <inertia ixx="0.7171" ixy="0" ixz=" 0" iyy="0.1361" iyz="0" izz="0.7171"/>
    </inertial>
    <visual>
      <!-- <origin xyz="0 0 0" rpy="0 0 0" /> -->
      <origin rpy="0 0 0" xyz="-0.221 -0.225 0.0925"/>
      <geometry>
        <mesh filename="package://scout_description/meshes/scout_mini/mini_wheel.dae"/>
      </geometry>
    </visual>
    <collision>
      <origin rpy="1.570795 0 0" xyz="0 0 0"/>
      <geometry>
        <cylinder length="0.0852" radius="0.0875"/>
      </geometry>
    </collision>
  </link>
  <joint name="rear_left_wheel" type="continuous">
    <parent link="base_link"/>
    <child link="rear_left_wheel_link"/>
    <origin rpy="0 0 0" xyz="-0.226 0.245 -0.0905"/>
    <axis rpy="0 0 0" xyz="0 -1 0"/>
  </joint>
  <link name="rear_right_wheel_link">
    <inertial>
      <mass value="1"/>
      <origin xyz="0 0 0"/>
      <inertia ixx="0.7171" ixy="0" ixz="0" iyy="0.1361" iyz="0" izz="0.7171"/>
    </inertial>
    <visual>
      <!-- <origin xyz="0 0 0" rpy="0 0 0" /> -->
      <origin rpy="0 0 0" xyz="-0.221 -0.225 0.0925"/>
      <geometry>
        <mesh filename="package://scout_description/meshes/scout_mini/mini_wheel.dae"/>
      </geometry>
    </visual>
    <collision>
      <origin rpy="1.570795 0 0" xyz="0 0 0"/>
      <geometry>
        <cylinder length="0.0852" radius="0.0875"/>
      </geometry>
    </collision>
  </link>
  <joint name="rear_right_wheel" type="continuous">
    <parent link="base_link"/>
    <child link="rear_right_wheel_link"/>
    <origin rpy="3.14 0 0" xyz="-0.226 -0.245 -0.0905"/>
    <axis rpy="0 0 0" xyz="0 -1 0"/>
  </joint>

  <joint name="lidar_joint" type="fixed">
      <parent link="base_link"/>
      <child link="base_scan" />
      <orign rpy="0 0 0" xyz="-0.064 0 0.7"/>
      <axis rpy="0 0 0" xyz='0 0 -1'/>
    </joint>

  <link name="base_scan">    
    <inertial>
      <mass value="0.01"/>
      <origin xyz="-0.052 0 0.111"/>
      <inertia ixx="0.001" ixy='0.00' ixz='0.00' iyy='0.001' iyz='0.000' izz='0.001'/>
    </inertial>

    <collision>
      <origin rpy='0 0 0' xyz='-0.052 0 0.111'/>
      <geometry>
        <cylinder radius='0.0508' length='0.055'/>
      </geometry>
    </collision>

    <visual>
      <origin rpy='0 0 0' xyz='-0.064 0 0.121'/>
      <geometry>
        <mesh filename="package://scout_description/meshes/scout_mini/lds.dae" scale="0.001 0.001 0.001"/>
      </geometry>
    </visual>

  </link>

  <gazebo reference="base_scan">
    <gravity>true</gravity>
    <sensor name="imu_sensor" type="imu">
      <always_on>true</always_on>
      <update_rate>100</update_rate>
      <visualize>true</visualize>
      <topic>__default_topic__</topic>
      <plugin filename="libgazebo_ros_imu_sensor.so" name="imu_plugin">
        <topicName>imu</topicName>
        <bodyName>base_scan</bodyName>
        <updateRateHZ>100.0</updateRateHZ>
        <gaussianNoise>0.0</gaussianNoise>
        <xyzOffset>0 0 0</xyzOffset>
        <rpyOffset>0 0 0</rpyOffset>
        <frameName>imu_link</frameName>
        <initialOrientationAsReference>false</initialOrientationAsReference>
      </plugin>
      <pose>0 0 0 0 0 0</pose>
    </sensor>
  </gazebo>
  <gazebo>
  <plugin filename="gz-sim-diff-drive-system" name="gz::sim::systems::DiffDrive">
      <!-- wheels -->
      <left_joint>rear_left_wheel</left_joint>
      <left_joint>front_left_wheel</left_joint>
      <right_joint>rear_right_wheel</right_joint>
      <right_joint>front_right_wheel</right_joint>

      <!-- kinematics -->
      <wheel_separation>0.287</wheel_separation>
      <wheel_radius>0.0875</wheel_radius>

      <!-- limits -->
      <max_linear_acceleration>3.5</max_linear_acceleration>

      <topic>cmd_vel</topic>


      <odom_topic>odom</odom_topic>
      <frame_id>odom</frame_id>
      <tf_topic>/tf</tf_topic>
      <odom_publisher_frequency>30</odom_publisher_frequency>
      <child_frame_id>base_footprint</child_frame_id>

    </plugin>

    <plugin filename="gz-sim-joint-state-publisher-system"
      name="gz::sim::systems::JointStatePublisher">
      <topic>joint_states</topic>
      <!-- <update_rate>30</update_rate> -->
      <joint_name>rear_left_wheel</joint_name>
      <joint_name>rear_right_wheel</joint_name>
      <joint_name>front_left_wheel</joint_name>
      <joint_name>front_right_wheel</joint_name>
    </plugin>    
  </gazebo>
</robot>

  <!-- <transmission name="front_right_wheel_trans" type="SimpleTransmission">
    <type>transmission_interface/SimpleTransmission</type>
    <actuator name="front_right_wheel_motor">
      <mechanicalReduction>1</mechanicalReduction>
    </actuator>
    <joint name="front_right_wheel">
      <hardwareInterface>hardware_interface/VelocityJointInterface</hardwareInterface>
    </joint>
  </transmission>
  <transmission name="front_left_wheel_trans" type="SimpleTransmission">
    <type>transmission_interface/SimpleTransmission</type>
    <actuator name="front_left_wheel_motor">
      <mechanicalReduction>1</mechanicalReduction>
    </actuator>
    <joint name="front_left_wheel">
      <hardwareInterface>hardware_interface/VelocityJointInterface</hardwareInterface>
    </joint>
  </transmission>
  <transmission name="rear_left_wheel_trans" type="SimpleTransmission">
    <type>transmission_interface/SimpleTransmission</type>
    <actuator name="rear_left_wheel_motor">
      <mechanicalReduction>1</mechanicalReduction>
    </actuator>
    <joint name="rear_left_wheel">
      <hardwareInterface>hardware_interface/VelocityJointInterface</hardwareInterface>
    </joint>
  </transmission>
  <transmission name="rear_right_wheel_trans" type="SimpleTransmission">
    <type>transmission_interface/SimpleTransmission</type>
    <actuator name="rear_right_wheel_motor">
      <mechanicalReduction>1</mechanicalReduction>
    </actuator>
    <joint name="rear_right_wheel">
      <hardwareInterface>hardware_interface/VelocityJointInterface</hardwareInterface>
    </joint>
  </transmission>
  <gazebo>
    <plugin filename="libgazebo_ros_control.so" name="gazebo_ros_control">
      <robotNamespace>/</robotNamespace>
    </plugin>
  </gazebo>
  <gazebo>
    <mu1 value="1.0"/>
    <mu2 value="0.9"/>
    <kp value="10000000.0"/>
    <kd value="1.0"/>
    <fdir1 value="1 0 0"/>
    <minDepth value="0.001"/>
    <maxContacts value="64"/>
  </gazebo> -->